root@429bf8a47512:/app/app# bash run_min_expr.sh
2024-11-13 10:14:15,799 INFO run.py:51 - fetch_and_update_ctx() :: Connected to database...
2024-11-13 10:14:15,816 INFO run.py:38 -            fetch_all() :: Total number: 13, analyzing 13 functions...
2024-11-13 10:14:15,818 INFO run.py:85 - preprocess_and_analyze() :: Connected to database...
2024-11-13 10:14:15,819 INFO run.py:38 -            fetch_all() :: Total number: 13, analyzing 13 functions...
2024-11-13 10:14:15,820 INFO run.py:92 - preprocess_and_analyze() :: Preprocessing function hv_pci_enter_d0 with context 	struct hv_pcibus_de...
suspicous varaible: comp_pkt.completion_status
use: if (comp_pkt.completion_status < 0) {

Code:
	struct hv_pcibus_device *hbus = hv_get_drvdata(hdev);
	struct pci_bus_d0_entry *d0_entry;
	struct hv_pci_compl comp_pkt;
	struct pci_packet *pkt;
	int ret;

	/*
	 * Tell the host that the bus is ready to use, and moved into the
	 * powered-on state.  This includes telling the host which region
	 * of memory-mapped I/O space has been chosen for configuration space
	 * access.
	 */
	pkt = kzalloc(sizeof(*pkt) + sizeof(*d0_entry), GFP_KERNEL);
	if (!pkt)
		return -ENOMEM;

	init_completion(&comp_pkt.host_event);
	pkt->completion_func = hv_pci_generic_compl;
	pkt->compl_ctxt = &comp_pkt;
	d0_entry = (struct pci_bus_d0_entry *)&pkt->message;
	d0_entry->message_type.type = PCI_BUS_D0ENTRY;
	d0_entry->mmio_base = hbus->mem_config->start;

	ret = vmbus_sendpacket(hdev->channel, d0_entry, sizeof(*d0_entry),
			       (unsigned long)pkt, VM_PKT_DATA_INBAND,
			       VMBUS_DATA_PACKET_FLAG_COMPLETION_REQUESTED);
	if (ret)
		goto exit;

	wait_for_completion(&comp_pkt.host_event);

	if (comp_pkt.completion_status < 0) {

2024-11-13 10:14:28,871 INFO call_api.py:73 -  call_gpt_preprocess() :: Initializer function for the variable comp_pkt.completion_status is: hv_pci_generic_compl;

The checks before the variable use are:

1. Completion is received from the host
It's represented by wait_for_completion(&comp_pkt.host_event);

2. The vmbus_sendpacket(hdev->channel, d0_entry, sizeof(*d0_entry),(unsigned long)pkt, VM_PKT_DATA_INBAND,VMBUS_DATA_PACKET_FLAG_COMPLETION_REQUESTED); function succeeds in sending packet.
This is represented by the check if (ret) goto exit; which means the function vmbus_sendpacket is not failed, if failed then the following code is skipped and it jumps to "exit". In this case, the check is represented by "ret == 0".

So, both conditions should be satisfied (connected by logical AND '&&') before the use of comp_pkt.completion_status.
2024-11-13 10:14:36,071 INFO call_api.py:85 -  call_gpt_preprocess() :: For the variable comp_pkt.completion_status, the initializer function is hv_pci_generic_compl, which does not have a return value and is not explicitly called. Instead, it is set as a callback function in the packet and it is triggered when the packet is completed by the host.

The packet is sent to the host through the function vmbus_sendpacket which returns a value. This return value is stored in the variable ret. If this return value is not zero (indicating an error on sending the packet), the program will go to label exit and skip the use of comp_pkt.completion_status. This check can be represented as "ret == 0".

After the packet is sent, the program waits for the completion event from the host through the function call wait_for_completion(&comp_pkt.host_event). This function will block the program until the event completes. This guarantees that the initializer function hv_pci_generic_compl has been called and comp_pkt.completion_status has been initialized.

Therefore, the variable comp_pkt.completion_status uses under two checks:

1) vmbus_sendpacket is successful (ret == 0)
2) the completion event from the host has been triggered (wait_for_completion(&comp_pkt.host_event))

These two checks can be combined with logical AND '&&', because both of them must be true before the use of comp_pkt.completion_status.

So, the final postcondition is: "ret == 0 && (completion event from the host is triggered)"

The final analysis of the task can be represented in JSON format as follows:

{
   "initializer": "hv_pci_generic_compl",
   "suspicious": ["comp_pkt.completion_status"],
   "postcondition": "ret == 0 && (completion event from the host is triggered)"
}
2024-11-13 10:14:39,919 INFO run.py:106 - preprocess_and_analyze() :: Skip analysis for function hv_pci_enter_d0, variable comp_pkt.completion_status with initializer {"error": "no json found!"}...
2024-11-13 10:14:39,919 INFO run.py:92 - preprocess_and_analyze() :: Preprocessing function pv_eoi_get_pending with context 	u8 val;
	if (pv_eoi...
suspicous varaible: val
use: return val & 0x1;

Code:
	u8 val;
	if (pv_eoi_get_user(vcpu, &val) < 0)
		apic_debug("Can't read EOI MSR value: 0x%llx\n",
			   (unsigned long long)vcpu->arch.pv_eoi.msr_val);
	return val & 0x1;

2024-11-13 10:14:44,418 INFO call_api.py:73 -  call_gpt_preprocess() :: The initializer for the suspicious variable `val` is the function `pv_eoi_get_user(vcpu, &val)`.

The check before use falls under "Type B. Return Code Failures". However, as there is no explicit control change (like return, break, goto) that prevents reaching the variable's use point with the "potential check", this check (`pv_eoi_get_user(vcpu, &val) < 0`) is disregarded as it provides no guarantee. The function `pv_eoi_get_user` may still return to its caller even if return value is less than zero, and the program will still hit the usage of `val`.

So based on the context, there's no valid check condition available before the usage of the variable `val`. The usage of variable `val` (`return val & 0x1;`) is not guarded by any checks.
2024-11-13 10:14:56,517 INFO call_api.py:85 -  call_gpt_preprocess() :: Given these rules, we can revisit our analysis.

The initializer here clearly is the `pv_eoi_get_user(vcpu, &val)`. As per the code, the return value from the initializer is not assigned to `val`. There's a condition check on the initializer `pv_eoi_get_user(vcpu, &val) < 0`, which is intended to print an error message but does not affect the execution flow.

We adhere to the principle that if the "use" is exactly a check, then it should be directly ignored in the postcondition extraction. Here `return val & 0x1`, is not a check and hence, needs to be considered.

Regarding the possible `goto` scenario, the provided context does not provide any such labels or branches that could be considered as part of the checks.

This provided snippet has a single initialization for 'val', meaning we do not need to consider combining multiple checks.

Nonetheless, there is an important point: we are dealing with an unguarded usage scenario meaning there are no checks or conditions preventing the usage of variable `val`.

Therefore, according to the context and instructions, there is no valid postcondition; hence, postcondition: null.
Based on the analysis, the conclusion in json format would be as follows:

```
{
   "initializer": "pv_eoi_get_user(vcpu, &val)",
   "suspicious": ["val"],
   "postcondition": null
}
```
2024-11-13 10:14:59,896 INFO run.py:117 - preprocess_and_analyze() :: analyzing pv_eoi_get_pending, variable val with initializer {"initializer": "pv_eoi_get_user(vcpu, &val)", "suspicious": ["val"], "postcondition": null}...
path: /v4.14/source/arch/x86/kvm/lapic.c
Traceback (most recent call last):
  File "/app/app/run.py", line 185, in <module>
    preprocess_and_analyze(args.group, args.max_id, args.min_id,
  File "/app/app/run.py", line 120, in preprocess_and_analyze
    result = do_analysis(sampling_res, case.last_round, case, model)
  File "/app/app/prompts/call_api.py", line 411, in do_analysis
    response = call_gpt_analysis(
  File "/app/app/prompts/call_api.py", line 128, in call_gpt_analysis
    func_def = get_func_def_easy(func_name)
  File "/app/app/helper/get_func_def.py", line 136, in get_func_def_easy
    return read_function_definition(file_path, line_number, linux_path)
  File "/app/app/helper/get_func_def.py", line 37, in read_function_definition
    with open(os.path.join(linux_path, file_path), 'r', errors='ignore') as f:
FileNotFoundError: [Errno 2] No such file or directory: '/v4.14/source/arch/x86/kvm/lapic.c'

